<?xml version="1.0" ?>
<!-- =================================================================================== -->
<!-- |    This document was autogenerated by xacro from heron.urdf.xacro               | -->
<!-- |    EDITING THIS FILE BY HAND IS NOT RECOMMENDED                                 | -->
<!-- =================================================================================== -->
<robot name="heron" xmlns:controller="http://playerstage.sourceforge.net/gazebo/xmlschema/#controller" xmlns:interface="http://playerstage.sourceforge.net/gazebo/xmlschema/#interface" xmlns:sensor="http://playerstage.sourceforge.net/gazebo/xmlschema/#sensor">
  <!--
    NOTE: the macro defined in this file is NOT part of the public API of this
          package. Users CANNOT rely on this file being available, or stored in
          this location. Nor can they rely on the existence of the macro.
  -->
  <!-- Defining material color -->
  <material name="mir_blue">
    <color rgba="0 0 0.8 1"/>
  </material>
  <material name="mir_white">
    <color rgba="1 1 1 1"/>
  </material>
  <!-- <link name="world"/> -->
  <!-- This file is only for backward compatibility before the "mir_100" to "mir" rename. -->
  <!-- necessary because args cannot be accessed inside ${} expressions -->
  <link name="mir/base_footprint"/>
  <joint name="mir/base_joint" type="fixed">
    <parent link="mir/base_footprint"/>
    <child link="mir/base_link"/>
    <origin rpy="0 0 0" xyz="0 0 0"/>
  </joint>
  <link name="mir/base_link">
    <inertial>
      <mass value="77.0"/>
      <origin rpy="0 0 0" xyz="-0.012354000000000004 0.0 0.15"/>
      <inertia ixx="0.8341663330000001" ixy="0.0" ixz="0.0" iyy="1.8608325890000004" iyz="0.0" izz="2.1816657939999997"/>
    </inertial>
    <visual>
      <origin rpy="0 0 0" xyz="0.037646 0 0"/>
      <geometry>
        <mesh filename="package://mir_description/meshes/visual/mir_100_base.stl"/>
      </geometry>
      <material name="white">
        <color rgba="1 1 1 1"/>
      </material>
    </visual>
    <collision>
      <origin rpy="0 0 0" xyz="0.037646 0 0"/>
      <geometry>
        <mesh filename="package://mir_description/meshes/collision/mir_100_base.stl"/>
      </geometry>
    </collision>
  </link>
  <gazebo reference="mir/base_link">
    <material>Gazebo/White</material>
  </gazebo>
  <!-- IMU -->
  <joint name="mir/base_link_to_imu_joint" type="fixed">
    <parent link="mir/base_link"/>
    <child link="mir/imu_link"/>
    <origin rpy="0 0 0" xyz="0.0 0.0 0.25"/>
    <!-- same as real MiR -->
  </joint>
  <link name="mir/imu_link"/>
  <gazebo>
    <plugin filename="libhector_gazebo_ros_imu.so" name="imu_plugin">
      <updateRate>50.0</updateRate>
      <bodyName>mir/imu_link</bodyName>
      <frameId>mir/imu_frame</frameId>
      <!-- from real MiR -->
      <topicName>imu_data</topicName>
      <accelDrift>0.0 0.0 0.0</accelDrift>
      <accelGaussianNoise>0.007071067811865475 0.01 0.011401754250991379</accelGaussianNoise>
      <!-- real MiR linear_acceleration_covariance: [5e-05, 0.0, 0.0, 0.0, 0.0001, 0.0, 0.0, 0.0, 0.00013] -->
      <rateDrift>0.0 0.0 0.0</rateDrift>
      <rateGaussianNoise>0.00282842712474619 0.00282842712474619 0.0005477225575051661</rateGaussianNoise>
      <!-- real MiR angular_velocity_covariance: [8e-06, 0.0, 0.0, 0.0, 8e-06, 0.0, 0.0, 0.0, 3e-07] -->
      <yawDrift>0.0</yawDrift>
      <yawGaussianNoise>0.31622776601683794</yawGaussianNoise>
      <!-- real MiR orientation_covariance: [0.1, 0.0, 0.0, 0.0, 0.1, 0.0, 0.0, 0.0, 0.1] -->
    </plugin>
  </gazebo>
  <!-- Create an alias for imu_link. This is necessary because the real MiR's
         TF has imu_link, but the imu_data topic is published in the imu_frame
         frame. -->
  <joint name="mir/imu_link_to_imu_frame_joint" type="fixed">
    <parent link="mir/imu_link"/>
    <child link="mir/imu_frame"/>
    <origin rpy="0 0 0" xyz="0 0 0"/>
  </joint>
  <link name="mir/imu_frame"/>
  <!-- Laser scanners -->
  <joint name="mir/base_link_to_front_laser_joint" type="fixed">
    <parent link="mir/base_link"/>
    <child link="mir/front_laser_link"/>
    <origin rpy="0.0 0.0 0.7853981633974483" xyz="0.42964600000000003 0.2358 0.1914"/>
  </joint>
  <link name="mir/front_laser_link">
    <visual>
      <origin rpy="3.141592653589793 0 0" xyz="0.0 0.0 0.0"/>
      <geometry>
        <mesh filename="package://mir_description/meshes/visual/sick_lms-100.stl"/>
      </geometry>
      <!-- <xacro:insert_block name="material_yellow" /> -->
      <material name="black">
        <color rgba="0.1 0.1 0.1 1"/>
      </material>
    </visual>
    <collision>
      <origin rpy="3.141592653589793 0 0" xyz="0.0 0.0 0.0"/>
      <geometry>
        <mesh filename="package://mir_description/meshes/visual/sick_lms-100.stl"/>
      </geometry>
    </collision>
    <inertial>
      <mass value="1.2"/>
      <origin xyz="0 0 0"/>
      <inertia ixx="0.005824997669999999" ixy="0.0" ixz="0.0" iyy="0.00585609765756" iyz="0.0" izz="0.00483609806556"/>
    </inertial>
  </link>
  <gazebo reference="mir/front_laser_link">
    <!-- <material value="Gazebo/Yellow" /> -->
    <material value="Gazebo/FlatBlack"/>
    <sensor name="mir/front_laser_link" type="ray">
      <pose>0 0 0 0 0 0</pose>
      <visualize>false</visualize>
      <update_rate>12.5</update_rate>
      <ray>
        <scan>
          <horizontal>
            <samples>541</samples>
            <resolution>1</resolution>
            <!-- has to be 1; actual resolution will be computed from number of samples + min_angle/max_angle -->
            <min_angle>-2.35619449615</min_angle>
            <max_angle>2.35619449615</max_angle>
          </horizontal>
        </scan>
        <range>
          <min>0.05</min>
          <max>29.0</max>
          <resolution>0.01</resolution>
        </range>
        <noise>
          <type>gaussian</type>
          <!-- Noise parameters based on published spec for S300 achieving
                 "+-29mm" accuracy at range < 3m (~0.01 of the range) at
                 1 sigma. -->
          <mean>0.0</mean>
          <stddev>0.01</stddev>
        </noise>
      </ray>
      <plugin filename="libgazebo_ros_laser.so" name="gazebo_ros_front_laser_link_controller">
        <frameName>mir/front_laser_link</frameName>
        <topicName>f_scan</topicName>
      </plugin>
    </sensor>
  </gazebo>
  <joint name="mir/base_link_to_back_laser_joint" type="fixed">
    <parent link="mir/base_link"/>
    <child link="mir/back_laser_link"/>
    <origin rpy="0.0 0.0 -2.356194490192345" xyz="-0.354354 -0.2358 0.1914"/>
  </joint>
  <link name="mir/back_laser_link">
    <visual>
      <origin rpy="3.141592653589793 0 0" xyz="0.0 0.0 0.0"/>
      <geometry>
        <mesh filename="package://mir_description/meshes/visual/sick_lms-100.stl"/>
      </geometry>
      <!-- <xacro:insert_block name="material_yellow" /> -->
      <material name="black">
        <color rgba="0.1 0.1 0.1 1"/>
      </material>
    </visual>
    <collision>
      <origin rpy="3.141592653589793 0 0" xyz="0.0 0.0 0.0"/>
      <geometry>
        <mesh filename="package://mir_description/meshes/visual/sick_lms-100.stl"/>
      </geometry>
    </collision>
    <inertial>
      <mass value="1.2"/>
      <origin xyz="0 0 0"/>
      <inertia ixx="0.005824997669999999" ixy="0.0" ixz="0.0" iyy="0.00585609765756" iyz="0.0" izz="0.00483609806556"/>
    </inertial>
  </link>
  <gazebo reference="mir/back_laser_link">
    <!-- <material value="Gazebo/Yellow" /> -->
    <material value="Gazebo/FlatBlack"/>
    <sensor name="mir/back_laser_link" type="ray">
      <pose>0 0 0 0 0 0</pose>
      <visualize>false</visualize>
      <update_rate>12.5</update_rate>
      <ray>
        <scan>
          <horizontal>
            <samples>541</samples>
            <resolution>1</resolution>
            <!-- has to be 1; actual resolution will be computed from number of samples + min_angle/max_angle -->
            <min_angle>-2.35619449615</min_angle>
            <max_angle>2.35619449615</max_angle>
          </horizontal>
        </scan>
        <range>
          <min>0.05</min>
          <max>29.0</max>
          <resolution>0.01</resolution>
        </range>
        <noise>
          <type>gaussian</type>
          <!-- Noise parameters based on published spec for S300 achieving
                 "+-29mm" accuracy at range < 3m (~0.01 of the range) at
                 1 sigma. -->
          <mean>0.0</mean>
          <stddev>0.01</stddev>
        </noise>
      </ray>
      <plugin filename="libgazebo_ros_laser.so" name="gazebo_ros_back_laser_link_controller">
        <frameName>mir/back_laser_link</frameName>
        <topicName>b_scan</topicName>
      </plugin>
    </sensor>
  </gazebo>
  <!-- Ultrasound sensors -->
  <joint name="mir/us_1_joint" type="fixed">
    <!-- right ultrasound -->
    <parent link="mir/base_link"/>
    <child link="mir/us_1_frame"/>
    <origin rpy="0 0 0" xyz="0.45 -0.12 0.16 "/>
    <!-- from visually matching to the mesh of the MiR -->
  </joint>
  <link name="mir/us_1_frame"/>
  <joint name="mir/us_2_joint" type="fixed">
    <!-- left ultrasound -->
    <parent link="mir/base_link"/>
    <child link="mir/us_2_frame"/>
    <origin rpy="0 0 0" xyz="0.45 0.12 0.16 "/>
    <!-- from visually matching to the mesh of the MiR -->
  </joint>
  <link name="mir/us_2_frame"/>
  <joint name="mir/left_wheel_joint" type="continuous">
    <origin rpy="0 0 0" xyz="0.0 0.222604 0.0625"/>
    <parent link="mir/base_link"/>
    <child link="mir/left_wheel_link"/>
    <axis xyz="0 1 0"/>
    <limit effort="100" velocity="20.0"/>
  </joint>
  <link name="mir/left_wheel_link">
    <inertial>
      <mass value="1.0"/>
      <origin rpy="1.5707963267948966 0 0" xyz="0 0 0"/>
      <inertia ixx="0.001061895408575" ixy="0.0" ixz="0.0" iyy="0.001061895408575" iyz="0.0" izz="0.001953125"/>
    </inertial>
    <visual>
      <origin rpy="1.5707963267948966 0 0" xyz="0 0 0"/>
      <geometry>
        <cylinder length="0.032" radius="0.0625"/>
      </geometry>
      <material name="black">
        <color rgba="0.1 0.1 0.1 1"/>
      </material>
    </visual>
    <collision>
      <origin rpy="1.5707963267948966 0 0" xyz="0 0 0"/>
      <geometry>
        <cylinder length="0.032" radius="0.0625"/>
      </geometry>
    </collision>
  </link>
  <gazebo reference="mir/left_wheel_link">
    <material>Gazebo/FlatBlack</material>
  </gazebo>
  <joint name="mir/right_wheel_joint" type="continuous">
    <origin rpy="0 0 0" xyz="0.0 -0.222604 0.0625"/>
    <parent link="mir/base_link"/>
    <child link="mir/right_wheel_link"/>
    <axis xyz="0 1 0"/>
    <limit effort="100" velocity="20.0"/>
  </joint>
  <link name="mir/right_wheel_link">
    <inertial>
      <mass value="1.0"/>
      <origin rpy="1.5707963267948966 0 0" xyz="0 0 0"/>
      <inertia ixx="0.001061895408575" ixy="0.0" ixz="0.0" iyy="0.001061895408575" iyz="0.0" izz="0.001953125"/>
    </inertial>
    <visual>
      <origin rpy="1.5707963267948966 0 0" xyz="0 0 0"/>
      <geometry>
        <cylinder length="0.032" radius="0.0625"/>
      </geometry>
      <material name="black">
        <color rgba="0.1 0.1 0.1 1"/>
      </material>
    </visual>
    <collision>
      <origin rpy="1.5707963267948966 0 0" xyz="0 0 0"/>
      <geometry>
        <cylinder length="0.032" radius="0.0625"/>
      </geometry>
    </collision>
  </link>
  <gazebo reference="mir/right_wheel_link">
    <material>Gazebo/FlatBlack</material>
  </gazebo>
  <!-- caster hub -->
  <joint name="mir/fl_caster_rotation_joint" type="continuous">
    <origin rpy="0 0 0" xyz="0.34134600000000004 0.203 0.1565"/>
    <parent link="mir/base_link"/>
    <child link="mir/fl_caster_rotation_link"/>
    <axis xyz="0 0 1"/>
    <dynamics damping="0.01" friction="0.0"/>
  </joint>
  <link name="mir/fl_caster_rotation_link">
    <inertial>
      <!-- <origin xyz="0 0 -0.042500000044" rpy="${0.5 * pi} ${24 * deg_to_rad} ${1.5 * pi}" /> -->
      <origin rpy="0.41887903200000004 0 1.5707963267948966 " xyz="0 0 -0.042500000044"/>
      <mass value="0.3097539019"/>
      <inertia ixx="0.0005844517978" ixy="0" ixz="0" iyy="0.00052872551237" iyz="0" izz="0.00017923555074"/>
    </inertial>
    <visual>
      <origin rpy="0 0 0" xyz="0 0 0"/>
      <geometry>
        <mesh filename="package://mir_description/meshes/visual/caster_wheel_base.stl"/>
      </geometry>
      <material name="silver">
        <color rgba="0.79 0.82 0.93 1"/>
      </material>
    </visual>
    <collision>
      <origin rpy="0 0 0" xyz="0 0 0"/>
      <geometry>
        <mesh filename="package://mir_description/meshes/collision/caster_wheel_base.stl"/>
      </geometry>
    </collision>
  </link>
  <gazebo reference="mir/fl_caster_rotation_link">
    <material>Gazebo/Grey</material>
  </gazebo>
  <!-- caster wheel -->
  <joint name="mir/fl_caster_wheel_joint" type="continuous">
    <origin rpy="0 0 0" xyz="-0.0382 0 -0.094"/>
    <parent link="mir/fl_caster_rotation_link"/>
    <child link="mir/fl_caster_wheel_link"/>
    <axis xyz="0 1 0"/>
  </joint>
  <link name="mir/fl_caster_wheel_link">
    <inertial>
      <mass value="1.0"/>
      <origin rpy="1.5707963267948966 0 0" xyz="0 0 0"/>
      <inertia ixx="0.001061895408575" ixy="0.0" ixz="0.0" iyy="0.001061895408575" iyz="0.0" izz="0.001953125"/>
    </inertial>
    <visual>
      <origin rpy="1.5707963267948966 0 0" xyz="0 0 0"/>
      <geometry>
        <cylinder length="0.032" radius="0.0625"/>
      </geometry>
      <material name="black">
        <color rgba="0.1 0.1 0.1 1"/>
      </material>
    </visual>
    <collision>
      <origin rpy="1.5707963267948966 0 0" xyz="0 0 0"/>
      <geometry>
        <cylinder length="0.032" radius="0.0625"/>
      </geometry>
    </collision>
  </link>
  <gazebo reference="mir/fl_caster_wheel_link">
    <material>Gazebo/FlatBlack</material>
  </gazebo>
  <!-- caster hub -->
  <joint name="mir/fr_caster_rotation_joint" type="continuous">
    <origin rpy="0 0 0" xyz="0.34134600000000004 -0.203 0.1565"/>
    <parent link="mir/base_link"/>
    <child link="mir/fr_caster_rotation_link"/>
    <axis xyz="0 0 1"/>
    <dynamics damping="0.01" friction="0.0"/>
  </joint>
  <link name="mir/fr_caster_rotation_link">
    <inertial>
      <!-- <origin xyz="0 0 -0.042500000044" rpy="${0.5 * pi} ${24 * deg_to_rad} ${1.5 * pi}" /> -->
      <origin rpy="0.41887903200000004 0 1.5707963267948966 " xyz="0 0 -0.042500000044"/>
      <mass value="0.3097539019"/>
      <inertia ixx="0.0005844517978" ixy="0" ixz="0" iyy="0.00052872551237" iyz="0" izz="0.00017923555074"/>
    </inertial>
    <visual>
      <origin rpy="0 0 0" xyz="0 0 0"/>
      <geometry>
        <mesh filename="package://mir_description/meshes/visual/caster_wheel_base.stl"/>
      </geometry>
      <material name="silver">
        <color rgba="0.79 0.82 0.93 1"/>
      </material>
    </visual>
    <collision>
      <origin rpy="0 0 0" xyz="0 0 0"/>
      <geometry>
        <mesh filename="package://mir_description/meshes/collision/caster_wheel_base.stl"/>
      </geometry>
    </collision>
  </link>
  <gazebo reference="mir/fr_caster_rotation_link">
    <material>Gazebo/Grey</material>
  </gazebo>
  <!-- caster wheel -->
  <joint name="mir/fr_caster_wheel_joint" type="continuous">
    <origin rpy="0 0 0" xyz="-0.0382 0 -0.094"/>
    <parent link="mir/fr_caster_rotation_link"/>
    <child link="mir/fr_caster_wheel_link"/>
    <axis xyz="0 1 0"/>
  </joint>
  <link name="mir/fr_caster_wheel_link">
    <inertial>
      <mass value="1.0"/>
      <origin rpy="1.5707963267948966 0 0" xyz="0 0 0"/>
      <inertia ixx="0.001061895408575" ixy="0.0" ixz="0.0" iyy="0.001061895408575" iyz="0.0" izz="0.001953125"/>
    </inertial>
    <visual>
      <origin rpy="1.5707963267948966 0 0" xyz="0 0 0"/>
      <geometry>
        <cylinder length="0.032" radius="0.0625"/>
      </geometry>
      <material name="black">
        <color rgba="0.1 0.1 0.1 1"/>
      </material>
    </visual>
    <collision>
      <origin rpy="1.5707963267948966 0 0" xyz="0 0 0"/>
      <geometry>
        <cylinder length="0.032" radius="0.0625"/>
      </geometry>
    </collision>
  </link>
  <gazebo reference="mir/fr_caster_wheel_link">
    <material>Gazebo/FlatBlack</material>
  </gazebo>
  <!-- caster hub -->
  <joint name="mir/bl_caster_rotation_joint" type="continuous">
    <origin rpy="0 0 0" xyz="-0.270154 0.203 0.1565"/>
    <parent link="mir/base_link"/>
    <child link="mir/bl_caster_rotation_link"/>
    <axis xyz="0 0 1"/>
    <dynamics damping="0.01" friction="0.0"/>
  </joint>
  <link name="mir/bl_caster_rotation_link">
    <inertial>
      <!-- <origin xyz="0 0 -0.042500000044" rpy="${0.5 * pi} ${24 * deg_to_rad} ${1.5 * pi}" /> -->
      <origin rpy="0.41887903200000004 0 1.5707963267948966 " xyz="0 0 -0.042500000044"/>
      <mass value="0.3097539019"/>
      <inertia ixx="0.0005844517978" ixy="0" ixz="0" iyy="0.00052872551237" iyz="0" izz="0.00017923555074"/>
    </inertial>
    <visual>
      <origin rpy="0 0 0" xyz="0 0 0"/>
      <geometry>
        <mesh filename="package://mir_description/meshes/visual/caster_wheel_base.stl"/>
      </geometry>
      <material name="silver">
        <color rgba="0.79 0.82 0.93 1"/>
      </material>
    </visual>
    <collision>
      <origin rpy="0 0 0" xyz="0 0 0"/>
      <geometry>
        <mesh filename="package://mir_description/meshes/collision/caster_wheel_base.stl"/>
      </geometry>
    </collision>
  </link>
  <gazebo reference="mir/bl_caster_rotation_link">
    <material>Gazebo/Grey</material>
  </gazebo>
  <!-- caster wheel -->
  <joint name="mir/bl_caster_wheel_joint" type="continuous">
    <origin rpy="0 0 0" xyz="-0.0382 0 -0.094"/>
    <parent link="mir/bl_caster_rotation_link"/>
    <child link="mir/bl_caster_wheel_link"/>
    <axis xyz="0 1 0"/>
  </joint>
  <link name="mir/bl_caster_wheel_link">
    <inertial>
      <mass value="1.0"/>
      <origin rpy="1.5707963267948966 0 0" xyz="0 0 0"/>
      <inertia ixx="0.001061895408575" ixy="0.0" ixz="0.0" iyy="0.001061895408575" iyz="0.0" izz="0.001953125"/>
    </inertial>
    <visual>
      <origin rpy="1.5707963267948966 0 0" xyz="0 0 0"/>
      <geometry>
        <cylinder length="0.032" radius="0.0625"/>
      </geometry>
      <material name="black">
        <color rgba="0.1 0.1 0.1 1"/>
      </material>
    </visual>
    <collision>
      <origin rpy="1.5707963267948966 0 0" xyz="0 0 0"/>
      <geometry>
        <cylinder length="0.032" radius="0.0625"/>
      </geometry>
    </collision>
  </link>
  <gazebo reference="mir/bl_caster_wheel_link">
    <material>Gazebo/FlatBlack</material>
  </gazebo>
  <!-- caster hub -->
  <joint name="mir/br_caster_rotation_joint" type="continuous">
    <origin rpy="0 0 0" xyz="-0.270154 -0.203 0.1565"/>
    <parent link="mir/base_link"/>
    <child link="mir/br_caster_rotation_link"/>
    <axis xyz="0 0 1"/>
    <dynamics damping="0.01" friction="0.0"/>
  </joint>
  <link name="mir/br_caster_rotation_link">
    <inertial>
      <!-- <origin xyz="0 0 -0.042500000044" rpy="${0.5 * pi} ${24 * deg_to_rad} ${1.5 * pi}" /> -->
      <origin rpy="0.41887903200000004 0 1.5707963267948966 " xyz="0 0 -0.042500000044"/>
      <mass value="0.3097539019"/>
      <inertia ixx="0.0005844517978" ixy="0" ixz="0" iyy="0.00052872551237" iyz="0" izz="0.00017923555074"/>
    </inertial>
    <visual>
      <origin rpy="0 0 0" xyz="0 0 0"/>
      <geometry>
        <mesh filename="package://mir_description/meshes/visual/caster_wheel_base.stl"/>
      </geometry>
      <material name="silver">
        <color rgba="0.79 0.82 0.93 1"/>
      </material>
    </visual>
    <collision>
      <origin rpy="0 0 0" xyz="0 0 0"/>
      <geometry>
        <mesh filename="package://mir_description/meshes/collision/caster_wheel_base.stl"/>
      </geometry>
    </collision>
  </link>
  <gazebo reference="mir/br_caster_rotation_link">
    <material>Gazebo/Grey</material>
  </gazebo>
  <!-- caster wheel -->
  <joint name="mir/br_caster_wheel_joint" type="continuous">
    <origin rpy="0 0 0" xyz="-0.0382 0 -0.094"/>
    <parent link="mir/br_caster_rotation_link"/>
    <child link="mir/br_caster_wheel_link"/>
    <axis xyz="0 1 0"/>
  </joint>
  <link name="mir/br_caster_wheel_link">
    <inertial>
      <mass value="1.0"/>
      <origin rpy="1.5707963267948966 0 0" xyz="0 0 0"/>
      <inertia ixx="0.001061895408575" ixy="0.0" ixz="0.0" iyy="0.001061895408575" iyz="0.0" izz="0.001953125"/>
    </inertial>
    <visual>
      <origin rpy="1.5707963267948966 0 0" xyz="0 0 0"/>
      <geometry>
        <cylinder length="0.032" radius="0.0625"/>
      </geometry>
      <material name="black">
        <color rgba="0.1 0.1 0.1 1"/>
      </material>
    </visual>
    <collision>
      <origin rpy="1.5707963267948966 0 0" xyz="0 0 0"/>
      <geometry>
        <cylinder length="0.032" radius="0.0625"/>
      </geometry>
    </collision>
  </link>
  <gazebo reference="mir/br_caster_wheel_link">
    <material>Gazebo/FlatBlack</material>
  </gazebo>
  <joint name="mir/base_link_surface_joint" type="fixed">
    <origin rpy="0 0 0" xyz="0.037646 0 0.352"/>
    <parent link="mir/base_link"/>
    <child link="mir/surface"/>
    <axis xyz="0 0 1"/>
  </joint>
  <link name="mir/surface"/>
  <transmission name="mir/left_wheel_trans">
    <type>transmission_interface/SimpleTransmission</type>
    <joint name="mir/left_wheel_joint">
      <hardwareInterface>hardware_interface/VelocityJointInterface</hardwareInterface>
    </joint>
    <actuator name="mir/left_wheel_motor">
      <hardwareInterface>hardware_interface/VelocityJointInterface</hardwareInterface>
      <mechanicalReduction>1</mechanicalReduction>
    </actuator>
  </transmission>
  <transmission name="mir/right_wheel_trans">
    <type>transmission_interface/SimpleTransmission</type>
    <joint name="mir/right_wheel_joint">
      <hardwareInterface>hardware_interface/VelocityJointInterface</hardwareInterface>
    </joint>
    <actuator name="mir/right_wheel_motor">
      <hardwareInterface>hardware_interface/VelocityJointInterface</hardwareInterface>
      <mechanicalReduction>1</mechanicalReduction>
    </actuator>
  </transmission>
  <gazebo reference="mir/left_wheel_link">
    <mu1 value="200"/>
    <mu2 value="200"/>
    <kp value="10000000.0"/>
    <kd value="1.0"/>
    <minDepth>0.01</minDepth>
  </gazebo>
  <gazebo reference="mir/right_wheel_link">
    <mu1 value="200"/>
    <mu2 value="200"/>
    <kp value="10000000.0"/>
    <kd value="1.0"/>
    <minDepth>0.01</minDepth>
  </gazebo>
  <gazebo reference="mir/fl_caster_wheel_link">
    <mu1 value="1"/>
    <mu2 value="1"/>
    <kp value="10000000.0"/>
    <kd value="1.0"/>
    <minDepth>0.01</minDepth>
  </gazebo>
  <gazebo reference="mir/fr_caster_wheel_link">
    <mu1 value="1"/>
    <mu2 value="1"/>
    <kp value="10000000.0"/>
    <kd value="1.0"/>
    <minDepth>0.01</minDepth>
  </gazebo>
  <gazebo reference="mir/bl_caster_wheel_link">
    <mu1 value="1"/>
    <mu2 value="1"/>
    <kp value="10000000.0"/>
    <kd value="1.0"/>
    <minDepth>0.01</minDepth>
  </gazebo>
  <gazebo reference="mir/br_caster_wheel_link">
    <mu1 value="1"/>
    <mu2 value="1"/>
    <kp value="10000000.0"/>
    <kd value="1.0"/>
    <minDepth>0.01</minDepth>
  </gazebo>
  <gazebo>
    <plugin filename="libgazebo_ros_p3d.so" name="p3d_base_controller">
      <alwaysOn>true</alwaysOn>
      <updateRate>50.0</updateRate>
      <bodyName>mir/base_footprint</bodyName>
      <topicName>base_pose_ground_truth</topicName>
      <gaussianNoise>0.01</gaussianNoise>
      <frameName>map</frameName>
      <xyzOffsets>0 0 0</xyzOffsets>
      <rpyOffsets>0 0 0</rpyOffsets>
    </plugin>
  </gazebo>
  <!-- Defining cabinet_centre -->
  <link name="mir/cabinet_centre">
    <visual>
      <geometry>
        <box size="0.76 0.46 0.5"/>
      </geometry>
      <material name="mir_blue"/>
    </visual>
    <collision>
      <geometry>
        <box size="0.76 0.46 0.5"/>
      </geometry>
    </collision>
  </link>
  <!-- Defining cabinet_pad -->
  <link name="mir/cabinet_pad">
    <visual>
      <geometry>
        <box size="0.25 0.29 0.02"/>
      </geometry>
      <material name="mir_white"/>
      <origin rpy="0 -1.0471975511965976 0" xyz="0 0 0"/>
    </visual>
    <collision>
      <geometry>
        <box size="0.25 0.29 0.02"/>
      </geometry>
      <origin rpy="0 -1.0471975511965976 0" xyz="0 0 0"/>
    </collision>
  </link>
  <!-- Defining cabinet_table-->
  <link name="mir/cabinet_table"/>
  <!-- Defining cabinet_lower-->
  <link name="mir/cabinet_lower"/>
  <!-- Defining cabinet_arm_base-->
  <link name="mir/cabinet_arm_base"/>
  <!-- Defining joints -->
  <joint name="mir/cabinet_pad_joint" type="fixed">
    <parent link="mir/cabinet_centre"/>
    <child link="mir/cabinet_pad"/>
    <origin xyz="-0.45 0 0.14"/>
  </joint>
  <joint name="mir/cabinet_table_joint" type="fixed">
    <parent link="mir/cabinet_centre"/>
    <child link="mir/cabinet_table"/>
    <origin xyz="-0.34 -0.19 0.25"/>
  </joint>
  <joint name="mir/cabinet_lower_joint" type="fixed">
    <parent link="mir/cabinet_centre"/>
    <child link="mir/cabinet_lower"/>
    <origin xyz="-0.38 -0.23 -0.25"/>
  </joint>
  <joint name="mir/cabinet_arm_base_joint" type="fixed">
    <parent link="mir/cabinet_table"/>
    <child link="mir/cabinet_arm_base"/>
    <origin xyz=" 0.2405 0.1855 0.02"/>
  </joint>
  <joint name="mir/cabinet_to_mir" type="fixed">
    <parent link="mir/surface"/>
    <child link="mir/cabinet_centre"/>
    <origin xyz="0 0 0.25"/>
  </joint>
  <!-- world to mir_base_footprint -->
  <!-- <joint name="$(arg prefix)base_footprint" type="fixed">
    <parent link="world"/>
    <child link = "$(arg prefix)base_footprint"/>
    <origin xyz="0 0 0"/>
  </joint> -->
  <!-- arm -->
  <joint name="arm_joint" type="fixed">
    <parent link="mir/cabinet_arm_base"/>
    <child link="ur5e_base_link"/>
    <origin rpy="0 0 -1.5707963267948966" xyz="0 0 0"/>
  </joint>
  <!-- measured from model -->
  <!-- link lengths used in model -->
  <!-- manually measured -->
  <link name="ur5e_base_link">
    <visual>
      <origin rpy="0 0 3.141592653589793" xyz="0 0 0"/>
      <geometry>
        <mesh filename="package://ur_description/meshes/ur5e/visual/base.dae"/>
      </geometry>
      <material name="LightGrey">
        <color rgba="0.7 0.7 0.7 1.0"/>
      </material>
    </visual>
    <collision>
      <origin rpy="0 0 3.141592653589793" xyz="0 0 0"/>
      <geometry>
        <mesh filename="package://ur_description/meshes/ur5e/collision/base.stl"/>
      </geometry>
    </collision>
    <inertial>
      <mass value="4.0"/>
      <origin rpy="0 0 0" xyz="0.0 0.0 0.0"/>
      <inertia ixx="0.00443333156" ixy="0.0" ixz="0.0" iyy="0.00443333156" iyz="0.0" izz="0.0072"/>
    </inertial>
  </link>
  <joint name="ur5e_shoulder_pan_joint" type="revolute">
    <parent link="ur5e_base_link"/>
    <child link="ur5e_shoulder_link"/>
    <origin rpy="0 0 3.141592653589793" xyz="0 0 0.1625"/>
    <axis xyz="0 0 1"/>
    <limit effort="150.0" lower="-6.283185307179586" upper="6.283185307179586" velocity="3.14"/>
    <dynamics damping="0.0" friction="0.0"/>
  </joint>
  <link name="ur5e_shoulder_link">
    <visual>
      <origin rpy="0 0 3.141592653589793" xyz="0 0 0"/>
      <geometry>
        <mesh filename="package://ur_description/meshes/ur5e/visual/shoulder.dae"/>
      </geometry>
      <material name="LightGrey">
        <color rgba="0.7 0.7 0.7 1.0"/>
      </material>
    </visual>
    <collision>
      <origin rpy="0 0 3.141592653589793" xyz="0 0 0"/>
      <geometry>
        <mesh filename="package://ur_description/meshes/ur5e/collision/shoulder.stl"/>
      </geometry>
    </collision>
    <inertial>
      <mass value="3.7"/>
      <origin rpy="0 0 0" xyz="0.0 0.0 0.0"/>
      <inertia ixx="0.010267495893" ixy="0.0" ixz="0.0" iyy="0.010267495893" iyz="0.0" izz="0.00666"/>
    </inertial>
  </link>
  <joint name="ur5e_shoulder_lift_joint" type="revolute">
    <parent link="ur5e_shoulder_link"/>
    <child link="ur5e_upper_arm_link"/>
    <origin rpy="1.570796327 0 0" xyz="0 0 0"/>
    <axis xyz="0 0 1"/>
    <limit effort="150.0" lower="-6.283185307179586" upper="6.283185307179586" velocity="3.14"/>
    <dynamics damping="0.0" friction="0.0"/>
  </joint>
  <link name="ur5e_upper_arm_link">
    <visual>
      <origin rpy="1.5707963267948966 0 -1.5707963267948966" xyz="0 0 0.138"/>
      <geometry>
        <mesh filename="package://ur_description/meshes/ur5e/visual/upperarm.dae"/>
      </geometry>
      <material name="LightGrey">
        <color rgba="0.7 0.7 0.7 1.0"/>
      </material>
    </visual>
    <collision>
      <origin rpy="1.5707963267948966 0 -1.5707963267948966" xyz="0 0 0.138"/>
      <geometry>
        <mesh filename="package://ur_description/meshes/ur5e/collision/upperarm.stl"/>
      </geometry>
    </collision>
    <inertial>
      <mass value="8.393"/>
      <origin rpy="0 1.5707963267948966 0" xyz="-0.2125 0.0 0.138"/>
      <inertia ixx="0.13813473641275" ixy="0.0" ixz="0.0" iyy="0.13813473641275" iyz="0.0" izz="0.0236053125"/>
    </inertial>
  </link>
  <joint name="ur5e_elbow_joint" type="revolute">
    <parent link="ur5e_upper_arm_link"/>
    <child link="ur5e_forearm_link"/>
    <origin rpy="0 0 0" xyz="-0.425 0 0"/>
    <axis xyz="0 0 1"/>
    <limit effort="150.0" lower="-3.141592653589793" upper="3.141592653589793" velocity="3.14"/>
    <dynamics damping="0.0" friction="0.0"/>
  </joint>
  <link name="ur5e_forearm_link">
    <visual>
      <origin rpy="1.5707963267948966 0 -1.5707963267948966" xyz="0 0 0.007"/>
      <geometry>
        <mesh filename="package://ur_description/meshes/ur5e/visual/forearm.dae"/>
      </geometry>
      <material name="LightGrey">
        <color rgba="0.7 0.7 0.7 1.0"/>
      </material>
    </visual>
    <collision>
      <origin rpy="1.5707963267948966 0 -1.5707963267948966" xyz="0 0 0.007"/>
      <geometry>
        <mesh filename="package://ur_description/meshes/ur5e/collision/forearm.stl"/>
      </geometry>
    </collision>
    <inertial>
      <mass value="2.275"/>
      <origin rpy="0 1.5707963267948966 0" xyz="-0.2125 0.0 0.007"/>
      <inertia ixx="0.0323610733888988" ixy="0.0" ixz="0.0" iyy="0.0323610733888988" iyz="0.0" izz="0.0063984375"/>
    </inertial>
  </link>
  <joint name="ur5e_wrist_1_joint" type="revolute">
    <parent link="ur5e_forearm_link"/>
    <child link="ur5e_wrist_1_link"/>
    <origin rpy="0 0 0" xyz="-0.3922 0 0.1333"/>
    <axis xyz="0 0 1"/>
    <limit effort="28.0" lower="-6.283185307179586" upper="6.283185307179586" velocity="6.28"/>
    <dynamics damping="0.0" friction="0.0"/>
  </joint>
  <link name="ur5e_wrist_1_link">
    <visual>
      <origin rpy="1.5707963267948966 0 0" xyz="0 0 -0.127"/>
      <geometry>
        <mesh filename="package://ur_description/meshes/ur5e/visual/wrist1.dae"/>
      </geometry>
      <material name="LightGrey">
        <color rgba="0.7 0.7 0.7 1.0"/>
      </material>
    </visual>
    <collision>
      <origin rpy="1.5707963267948966 0 0" xyz="0 0 -0.127"/>
      <geometry>
        <mesh filename="package://ur_description/meshes/ur5e/collision/wrist1.stl"/>
      </geometry>
    </collision>
    <inertial>
      <mass value="1.219"/>
      <origin rpy="0 0 0" xyz="0.0 0.0 0.0"/>
      <inertia ixx="0.002723965136246843" ixy="0.0" ixz="0.0" iyy="0.002723965136246843" iyz="0.0" izz="0.0034284375"/>
    </inertial>
  </link>
  <joint name="ur5e_wrist_2_joint" type="revolute">
    <parent link="ur5e_wrist_1_link"/>
    <child link="ur5e_wrist_2_link"/>
    <origin rpy="1.570796327 0 0" xyz="0 -0.0997 -2.044881182297852e-11"/>
    <axis xyz="0 0 1"/>
    <limit effort="28.0" lower="-6.283185307179586" upper="6.283185307179586" velocity="6.28"/>
    <dynamics damping="0.0" friction="0.0"/>
  </joint>
  <link name="ur5e_wrist_2_link">
    <visual>
      <origin rpy="0 0 0" xyz="0 0 -0.0997"/>
      <geometry>
        <mesh filename="package://ur_description/meshes/ur5e/visual/wrist2.dae"/>
      </geometry>
      <material name="LightGrey">
        <color rgba="0.7 0.7 0.7 1.0"/>
      </material>
    </visual>
    <collision>
      <origin rpy="0 0 0" xyz="0 0 -0.0997"/>
      <geometry>
        <mesh filename="package://ur_description/meshes/ur5e/collision/wrist2.stl"/>
      </geometry>
    </collision>
    <inertial>
      <mass value="1.219"/>
      <origin rpy="0 0 0" xyz="0.0 0.0 0.0"/>
      <inertia ixx="0.002721940581223332" ixy="0.0" ixz="0.0" iyy="0.002721940581223332" iyz="0.0" izz="0.0034284375"/>
    </inertial>
  </link>
  <joint name="ur5e_wrist_3_joint" type="revolute">
    <parent link="ur5e_wrist_2_link"/>
    <child link="ur5e_wrist_3_link"/>
    <origin rpy="1.570796326589793 3.141592653589793 3.141592653589793" xyz="0 0.0996 -2.042830148012698e-11"/>
    <axis xyz="0 0 1"/>
    <limit effort="28.0" lower="-6.283185307179586" upper="6.283185307179586" velocity="6.28"/>
    <dynamics damping="0.0" friction="0.0"/>
  </joint>
  <link name="ur5e_wrist_3_link">
    <visual>
      <origin rpy="1.5707963267948966 0 0" xyz="0 0 -0.0989"/>
      <geometry>
        <mesh filename="package://ur_description/meshes/ur5e/visual/wrist3.dae"/>
      </geometry>
      <material name="LightGrey">
        <color rgba="0.7 0.7 0.7 1.0"/>
      </material>
    </visual>
    <collision>
      <origin rpy="1.5707963267948966 0 0" xyz="0 0 -0.0989"/>
      <geometry>
        <mesh filename="package://ur_description/meshes/ur5e/collision/wrist3.stl"/>
      </geometry>
    </collision>
    <inertial>
      <mass value="0.1879"/>
      <origin rpy="0 0 0" xyz="0.0 0.0 -0.025"/>
      <inertia ixx="0.00013427015462525002" ixy="0.0" ixz="0.0" iyy="0.00013427015462525002" iyz="0.0" izz="0.00019024874999999997"/>
    </inertial>
  </link>
  <joint name="ur5e_ee_fixed_joint" type="fixed">
    <parent link="ur5e_wrist_3_link"/>
    <child link="ur5e_ee_link"/>
    <origin rpy="0.0 -1.5707963267948966 1.5707963267948966" xyz="0.0 0.0 0.0"/>
  </joint>
  <link name="ur5e_ee_link">
    <collision>
      <geometry>
        <box size="0.01 0.01 0.01"/>
      </geometry>
      <origin rpy="0 0 0" xyz="-0.01 0 0"/>
    </collision>
  </link>
  <transmission name="ur5e_shoulder_pan_trans">
    <type>transmission_interface/SimpleTransmission</type>
    <joint name="ur5e_shoulder_pan_joint">
      <hardwareInterface>hardware_interface/PositionJointInterface</hardwareInterface>
    </joint>
    <actuator name="ur5e_shoulder_pan_motor">
      <mechanicalReduction>1</mechanicalReduction>
    </actuator>
  </transmission>
  <transmission name="ur5e_shoulder_lift_trans">
    <type>transmission_interface/SimpleTransmission</type>
    <joint name="ur5e_shoulder_lift_joint">
      <hardwareInterface>hardware_interface/PositionJointInterface</hardwareInterface>
    </joint>
    <actuator name="ur5e_shoulder_lift_motor">
      <mechanicalReduction>1</mechanicalReduction>
    </actuator>
  </transmission>
  <transmission name="ur5e_elbow_trans">
    <type>transmission_interface/SimpleTransmission</type>
    <joint name="ur5e_elbow_joint">
      <hardwareInterface>hardware_interface/PositionJointInterface</hardwareInterface>
    </joint>
    <actuator name="ur5e_elbow_motor">
      <mechanicalReduction>1</mechanicalReduction>
    </actuator>
  </transmission>
  <transmission name="ur5e_wrist_1_trans">
    <type>transmission_interface/SimpleTransmission</type>
    <joint name="ur5e_wrist_1_joint">
      <hardwareInterface>hardware_interface/PositionJointInterface</hardwareInterface>
    </joint>
    <actuator name="ur5e_wrist_1_motor">
      <mechanicalReduction>1</mechanicalReduction>
    </actuator>
  </transmission>
  <transmission name="ur5e_wrist_2_trans">
    <type>transmission_interface/SimpleTransmission</type>
    <joint name="ur5e_wrist_2_joint">
      <hardwareInterface>hardware_interface/PositionJointInterface</hardwareInterface>
    </joint>
    <actuator name="ur5e_wrist_2_motor">
      <mechanicalReduction>1</mechanicalReduction>
    </actuator>
  </transmission>
  <transmission name="ur5e_wrist_3_trans">
    <type>transmission_interface/SimpleTransmission</type>
    <joint name="ur5e_wrist_3_joint">
      <hardwareInterface>hardware_interface/PositionJointInterface</hardwareInterface>
    </joint>
    <actuator name="ur5e_wrist_3_motor">
      <mechanicalReduction>1</mechanicalReduction>
    </actuator>
  </transmission>
  <!-- Load Gazebo lib and set the robot namespace -->
  <!-- <gazebo>
      <plugin name="gazebo_ros_control" filename="libgazebo_ros_control.so">
        <robotNamespace>/${prefix}</robotNamespace>
        <robotSimType>heron_gazebo/AngularErrorFixHWSim</robotSimType>
        <legacyModeNS>true</legacyModeNS>

      </plugin>
    </gazebo> -->
  <gazebo reference="ur5e_shoulder_link">
    <turnGravityOff>true</turnGravityOff>
    <selfCollide>true</selfCollide>
  </gazebo>
  <gazebo reference="ur5e_upper_arm_link">
    <turnGravityOff>true</turnGravityOff>
    <selfCollide>true</selfCollide>
  </gazebo>
  <gazebo reference="ur5e_forearm_link">
    <turnGravityOff>true</turnGravityOff>
    <selfCollide>true</selfCollide>
  </gazebo>
  <gazebo reference="ur5e_wrist_1_link">
    <turnGravityOff>true</turnGravityOff>
    <selfCollide>true</selfCollide>
  </gazebo>
  <gazebo reference="ur5e_wrist_3_link">
    <turnGravityOff>true</turnGravityOff>
    <selfCollide>true</selfCollide>
  </gazebo>
  <gazebo reference="ur5e_wrist_2_link">
    <turnGravityOff>true</turnGravityOff>
    <selfCollide>true</selfCollide>
  </gazebo>
  <gazebo reference="ur5e_ee_link">
    <turnGravityOff>true</turnGravityOff>
    <selfCollide>true</selfCollide>
  </gazebo>
  <!-- ROS base_link to UR 'Base' Coordinates transform -->
  <link name="ur5e_base"/>
  <joint name="ur5e_base_link-base_fixed_joint" type="fixed">
    <!-- NOTE: this rotation is only needed as long as base_link itself is
                 not corrected wrt the real robot (ie: rotated over 180
                 degrees)
      -->
    <origin rpy="0 0 -3.141592653589793" xyz="0 0 0"/>
    <parent link="ur5e_base_link"/>
    <child link="ur5e_base"/>
  </joint>
  <!-- Frame coincident with all-zeros TCP on UR controller -->
  <link name="ur5e_tool0"/>
  <joint name="ur5e_wrist_3_link-tool0_fixed_joint" type="fixed">
    <origin rpy="0 0 0" xyz="0 0 0"/>
    <parent link="ur5e_wrist_3_link"/>
    <child link="ur5e_tool0"/>
  </joint>
  <!-- connector plate -->
  <joint name="gripper_connector" type="fixed">
    <origin rpy="-1.5707963267948966 0 0" xyz="0 0 0"/>
    <parent link="ur5e_ee_link"/>
    <child link="connector_plate"/>
  </joint>
  <link name="connector_plate">
    <visual>
      <origin rpy="0 0 0" xyz="0.01 0 0"/>
      <geometry>
        <box size="0.02 0.09 0.09"/>
      </geometry>
      <material name="Grey"/>
    </visual>
    <collision>
      <origin rpy="0 0 0" xyz="0.01 0 0"/>
      <geometry>
        <box size="0.02 0.09 0.09"/>
      </geometry>
    </collision>
  </link>
  <!-- the actual gripper main component -->
  <joint name="schunk_gripper" type="fixed">
    <origin rpy="0 0 0" xyz="0.02 0 0"/>
    <parent link="connector_plate"/>
    <child link="gripper_link"/>
  </joint>
  <link name="gripper_link">
    <inertial>
      <origin xyz="0.05 0 0"/>
      <mass value="1.2"/>
      <inertia ixx="0.0023815990473599995" ixy="0.0" ixz="0.0" iyy="0.00077562468975" iyz="0.0" izz="0.0026572239371099996"/>
    </inertial>
    <visual>
      <!--<origin xyz="0 0 0 " rpy="0 0 1.570796327" />-->
      <origin rpy="0 0 0" xyz="0.03625 0 0"/>
      <geometry>
        <!--<mesh filename="package://bh_description/urdf/schunk_wsg50/schunk_wsg50_main.dae" scale="0.0254 0.0254 0.0254"/>-->
        <box size="0.0725 0.146 0.05"/>
      </geometry>
    </visual>
    <collision>
      <origin rpy="0 0 0" xyz="0.03625 0 0"/>
      <geometry>
        <box size="0.0725 0.146 0.05"/>
      </geometry>
    </collision>
  </link>
  <!-- Finger 1 -->
  <joint name="gripper_finger1_joint" type="fixed">
    <origin rpy="0 0 0" xyz="0.0725 0 0.0"/>
    <parent link="gripper_link"/>
    <child link="finger1_link"/>
  </joint>
  <link name="finger1_link">
    <visual>
      <!--<origin xyz="0 -0.05 0 " rpy="${-PI/2} 0 ${-PI/2}" />-->
      <origin rpy="0 0 0" xyz="0.05 -0.059 0"/>
      <geometry>
        <box size="0.1 0.018 0.03"/>
        <!--<mesh filename="package://bh_description/urdf/schunk_wsg50/finger.dae" scale="0.0254 0.0254 0.0254"/>-->
      </geometry>
      <!--<material name="Grey"/>-->
    </visual>
    <collision>
      <!--<origin xyz="0 -0.05 0 " rpy="${-PI/2} 0 ${-PI/2}" />-->
      <origin rpy="0 0 0" xyz="0.05 -0.059 0"/>
      <geometry>
        <!--<mesh filename="package://bh_description/urdf/schunk_wsg50/finger.dae" scale="0.0254 0.0254 0.0254"/>-->
        <box size="0.1 0.018 0.03"/>
      </geometry>
    </collision>
    <inertial>
      <origin rpy="0 0 0" xyz="0.05 -0.059 0"/>
      <mass value="0.4"/>
      <inertia ixx="3.2699986919999994e-05" ixy="0.0" ixz="0.0" iyy="0.00011333328800000001" iyz="0.0" izz="8.603329892000001e-05"/>
    </inertial>
  </link>
  <!-- Finger 2 -->
  <joint name="gripper_finger2_joint" type="fixed">
    <origin rpy="0 0 0" xyz="0.0725 0 0.0"/>
    <parent link="gripper_link"/>
    <child link="finger2_link"/>
  </joint>
  <link name="finger2_link">
    <visual>
      <!--<origin xyz="0 0.05 0 " rpy="${PI/2} 0 ${PI/2}" />-->
      <origin rpy="0 0 0" xyz="0.05 0.059 0"/>
      <geometry>
        <!--<mesh filename="package://bh_description/urdf/schunk_wsg50/finger.dae" scale="0.0254 0.0254 0.0254"/>-->
        <box size="0.1 0.018 0.03"/>
      </geometry>
      <!--<material name="Grey"/>-->
    </visual>
    <collision>
      <!--<origin xyz="0 0.05 0 " rpy="${PI/2} 0 ${PI/2}" />-->
      <origin rpy="0 0 0" xyz="0.05 0.059 0"/>
      <geometry>
        <!--<mesh filename="package://bh_description/urdf/schunk_wsg50/finger.dae" scale="0.0254 0.0254 0.0254"/>-->
        <box size="0.1 0.018 0.03"/>
      </geometry>
    </collision>
    <inertial>
      <origin rpy="0 0 0" xyz="0.05 0.059 0"/>
      <mass value="0.4"/>
      <inertia ixx="3.2699986919999994e-05" ixy="0.0" ixz="0.0" iyy="0.00011333328800000001" iyz="0.0" izz="8.603329892000001e-05"/>
    </inertial>
  </link>
  <gazebo reference="connector_plate">
    <turnGravityOff>true</turnGravityOff>
    <material>Gazebo/Gold</material>
    <mu1>0.2</mu1>
    <mu2>0.2</mu2>
  </gazebo>
  <gazebo reference="gripper_link">
    <turnGravityOff>true</turnGravityOff>
    <material>Gazebo/Gold</material>
    <mu1>0.2</mu1>
    <mu2>0.2</mu2>
  </gazebo>
  <gazebo reference="finger1_link">
    <turnGravityOff>true</turnGravityOff>
    <material>Gazebo/Gold</material>
    <mu1>0.2</mu1>
    <mu2>0.2</mu2>
  </gazebo>
  <gazebo reference="finger2_link">
    <turnGravityOff>true</turnGravityOff>
    <material>Gazebo/Gold</material>
    <mu1>0.2</mu1>
    <mu2>0.2</mu2>
  </gazebo>
  <!-- Finger 1 -->
  <!--<joint name="gripper_finger1_joint" type="prismatic">-->
  <!--<origin xyz="0.0725 0 0.0" rpy="0 0 0"/>-->
  <!--<parent link="gripper_link" />-->
  <!--<child link="finger1_link" />-->
  <!--<axis xyz="0 1 0"/>-->
  <!--<limit lower="-0.055" upper="0" velocity="0.400" effort="80"/>-->
  <!--</joint>-->
  <!--<link name="finger1_link">-->
  <!--<visual>-->
  <!--<origin xyz="0 0 0 " rpy="-1.570796327 0 -1.570796327" />-->
  <!--<geometry>-->
  <!--<mesh filename="package://bh_description/urdf/schunk_wsg50/finger.dae"/>-->
  <!--</geometry>-->
  <!--</visual>-->
  <!--<collision>-->
  <!--<origin xyz="0.05 -0.009 0" rpy="0 0 0" />-->
  <!--<geometry>-->
  <!--<box size="0.1 0.018 0.03"/>-->
  <!--<mesh filename="package://bh_description/urdf/schunk_wsg50/finger.dae" scale="0.0254 0.0254 0.0254"/>-->
  <!--</geometry>-->
  <!--</collision>-->
  <!--</link>-->
  <!-- Finger 2 -->
  <!--<joint name="gripper_finger2_joint" type="prismatic">-->
  <!--<origin xyz="0.0725 0 0.0" rpy="0 0 0"/>-->
  <!--<parent link="gripper_link" />-->
  <!--<child link="finger2_link" />-->
  <!--<axis xyz="0 1 0"/>-->
  <!--<limit lower="0" upper="0.055" velocity="0.400" effort="80"/>-->
  <!--<mimic joint="finger2_joint" multiplier="1" offset="0"/>-->
  <!--</joint>-->
  <!--<link name="finger2_link">-->
  <!--<visual>-->
  <!--<origin xyz="0 0 0 " rpy="1.570796327 0 1.570796327" />-->
  <!--<geometry>-->
  <!--<mesh filename="package://bh_description/urdf/schunk_wsg50/finger.dae"/>-->
  <!--</geometry>-->
  <!--</visual>-->
  <!--<collision>-->
  <!--<origin xyz="0.05 0.009 0" rpy="0 0 0" />-->
  <!--<geometry>-->
  <!--<box size="0.1 0.018 0.03"/>-->
  <!--<mesh filename="package://bh_description/urdf/schunk_wsg50/finger.dae" scale="0.0254 0.0254 0.0254">-->
  <!--</geometry>-->
  <!--</collision>-->
  <!--</link>-->
  <!-- frames for groove and tip -->
  <!--<joint name="gripper_groove_joint" type="fixed">-->
  <!--<origin xyz="0.135 0 0"/>-->
  <!--<parent link="gripper_link"/>-->
  <!--<child link="gripper_groove_frame"/>-->
  <!--</joint>-->
  <!--<link name="gripper_groove_frame"/>-->
  <!--<joint name="gripper_tip_joint" type="fixed">-->
  <!--<origin xyz="0.1725 0 0"/>-->
  <!--<parent link="gripper_link"/>-->
  <!--<child link="gripper_tip_frame"/>-->
  <!--</joint>-->
  <!--<link name="gripper_tip_frame"/>-->
  <!-- joint saying how much the gripper is open -->
  <!--<joint name="gripper_joint" type="prismatic">-->
  <!--<parent link="gripper_link"/>-->
  <!--<child link="gripper_joint"/>-->
  <!--<axis xyz="0 1 0"/>-->
  <!--<limit lower="0" upper="0.11" velocity="0.400" effort="80"/>-->
  <!--</joint>-->
  <!--<link name="gripper_joint"/>-->
  <!-- ur5e_tcp_link + joint-->
  <link name="ur5e_tcp_link"/>
  <joint name="ur5e_tcp_joint" type="fixed">
    <parent link="gripper_link"/>
    <child link="ur5e_tcp_link"/>
    <origin rpy="0.0 1.5707963267948966 0.0" xyz="0.072 0.0 0.0"/>
  </joint>
  <joint name="realsense_frame_joint" type="floating">
    <origin rpy="-1.5707963267948966 0 0" xyz="0.05 0.06 0.06"/>
    <parent link="ur5e_ee_link"/>
    <child link="realsense_link"/>
  </joint>
  <link name="realsense_link">
    <inertial>
      <mass value="0.1"/>
      <origin rpy="0 0 0" xyz="0 0 0"/>
      <inertia ixx="0.01" ixy="0.0" ixz="0.0" iyy="0.01" iyz="0.0" izz="0.01"/>
    </inertial>
    <visual>
      <origin rpy="1.57075 0 -1.57075" xyz="-0.02 0.0 0.0"/>
      <geometry>
        <!--<mesh filename="package://heron_description/urdf/primesense/primesense_collision.stl" scale="0.001 0.001 0.001" /> -->
        <box size="0.17 0.035 0.045"/>
      </geometry>
      <material name="DarkGrayBlack">
        <color rgba="0.1 0.1 0.1 1.0"/>
      </material>
    </visual>
    <collision>
      <origin rpy="1.57075 0 -1.57075" xyz="-0.02 0.0 0.0"/>
      <geometry>
        <!--<mesh filename="package://heron_description/urdf/primesense/primesense_collision.stl" scale="0.001 0.001 0.001" /> -->
        <box size="0.17 0.035 0.045"/>
      </geometry>
    </collision>
  </link>
  <gazebo reference="realsense_link">
    <turnGravityOff>true</turnGravityOff>
    <material>Gazebo/Gold</material>
    <mu1>10.0</mu1>
    <mu2>10.0</mu2>
    <sensor name="realsense_frame_sensor" type="depth">
      <always_on>true</always_on>
      <update_rate>20.0</update_rate>
      <camera>
        <horizontal_fov>1.0000441666666666</horizontal_fov>
        <image>
          <format>B8G8R8</format>
          <width>640</width>
          <height>480</height>
        </image>
        <clip>
          <near>0.1</near>
          <far>5</far>
        </clip>
      </camera>
      <plugin filename="libgazebo_ros_openni_kinect.so" name="realsense_frame_controller">
        <alwaysOn>true</alwaysOn>
        <updateRate>20.0</updateRate>
        <cameraName>realsense</cameraName>
        <imageTopicName>rgb/image_raw</imageTopicName>
        <cameraInfoTopicName>rgb/camera_info</cameraInfoTopicName>
        <depthImageTopicName>depth/image_raw</depthImageTopicName>
        <depthImageCameraInfoTopicName>depth/camera_info</depthImageCameraInfoTopicName>
        <pointCloudTopicName>depth/points</pointCloudTopicName>
        <frameName>realsense_rgb_optical_frame</frameName>
        <distortionK1>0.00000001</distortionK1>
        <distortionK2>0.00000001</distortionK2>
        <distortionK3>0.00000001</distortionK3>
        <distortionT1>0.00000001</distortionT1>
        <distortionT2>0.00000001</distortionT2>
        <!--         <baseline>0.2</baseline>
        <CxPrime>320.0</CxPrime>
        <Cx>320.0</Cx>
        <Cy>240.0</Cy>
 -->
        <pointCloudCutoff>0.01</pointCloudCutoff>
        <!-- <focal_length>320</focal_length> -->
        <!-- <hackBaseline>0</hackBaseline> -->
      </plugin>
    </sensor>
  </gazebo>
  <!-- The ft_sensor plugin -->
  <gazebo reference="ur5e_wrist_3_joint">
    <provideFeedback>true</provideFeedback>
  </gazebo>
  <gazebo>
    <plugin filename="libgazebo_ros_ft_sensor.so" name="ft_sensor">
      <updateRate>500.0</updateRate>
      <topicName>/wrench</topicName>
      <jointName>ur5e_wrist_3_joint</jointName>
      <!-- <noise>
          <type>gaussian</type>
          <mean>0.0</mean>
          <stddev>0.003</stddev> 
        </noise> -->
    </plugin>
  </gazebo>
  <!-- Load Gazebo lib and set the robot namespace <robotNamespace>/</robotNamespace> -->
  <gazebo>
    <plugin filename="libgazebo_ros_control.so" name="gazebo_ros_control">
      <robotSimType>heron_gazebo/AngularErrorFixHWSim</robotSimType>
      <robotParam>/robot_description</robotParam>
      <!-- 500Hz is the default for commanding the real UR -->
      <!-- Settings this causes issues with Gazebo. The arm would do a fast movement when being started. -->
      <!-- <controlPeriod>0.002</controlPeriod> -->
    </plugin>
  </gazebo>
</robot>
